2019-09-07 12:11:57,473 - root - ERROR - Failed to connect to MySQL
Traceback (most recent call last):
  File "optimized.py", line 54, in <module>
    engine = mySQL_connect(credentials_path, port='3306', db='test_schema')
NameError: name 'credentials_path' is not defined
2019-09-07 12:12:53,672 - root - ERROR - Failed to connect to MySQL
Traceback (most recent call last):
  File "optimized.py", line 54, in <module>
    engine = mySQL_connect(credentials, port='3306', db='test_schema')
NameError: name 'credentials' is not defined
2019-09-10 20:49:49,908 - sqlalchemy.pool.impl.QueuePool - ERROR - Exception during reset or similar
Traceback (most recent call last):
  File "/home/wayned/.virtualenvs/acquiredatabase/lib/python3.7/site-packages/pymysql/connections.py", line 691, in _read_bytes
    data = self._rfile.read(num_bytes)
  File "/home/wayned/anaconda3/lib/python3.7/socket.py", line 589, in readinto
    return self._sock.recv_into(b)
TimeoutError: [Errno 110] Connection timed out

During handling of the above exception, another exception occurred:

Traceback (most recent call last):
  File "/home/wayned/.virtualenvs/acquiredatabase/lib/python3.7/site-packages/sqlalchemy/pool/base.py", line 680, in _finalize_fairy
    fairy._reset(pool)
  File "/home/wayned/.virtualenvs/acquiredatabase/lib/python3.7/site-packages/sqlalchemy/pool/base.py", line 867, in _reset
    pool._dialect.do_rollback(self)
  File "/home/wayned/.virtualenvs/acquiredatabase/lib/python3.7/site-packages/sqlalchemy/dialects/mysql/base.py", line 2253, in do_rollback
    dbapi_connection.rollback()
  File "/home/wayned/.virtualenvs/acquiredatabase/lib/python3.7/site-packages/pymysql/connections.py", line 430, in rollback
    self._read_ok_packet()
  File "/home/wayned/.virtualenvs/acquiredatabase/lib/python3.7/site-packages/pymysql/connections.py", line 394, in _read_ok_packet
    pkt = self._read_packet()
  File "/home/wayned/.virtualenvs/acquiredatabase/lib/python3.7/site-packages/pymysql/connections.py", line 657, in _read_packet
    packet_header = self._read_bytes(4)
  File "/home/wayned/.virtualenvs/acquiredatabase/lib/python3.7/site-packages/pymysql/connections.py", line 699, in _read_bytes
    "Lost connection to MySQL server during query (%s)" % (e,))
pymysql.err.OperationalError: (2013, 'Lost connection to MySQL server during query ([Errno 110] Connection timed out)')
