2019-10-04 17:34:22,927 - database.upsert - ERROR - 362 - Encountered an error - retrys remaining: 2
Traceback (most recent call last):
  File "/home/ubuntu/facebook_to_db/database/upsert.py", line 306, in <module>
    fields=agegender_fields
  File "/home/ubuntu/facebook_to_db/database/database_functions.py", line 265, in get_request
    request = cursor.get_result(params={"limit": 1000})
  File "/home/ubuntu/.virtualenvs/acquiredatabase/lib/python3.7/site-packages/facebook_business/adobjects/helpers/adreportrunmixin.py", line 28, in get_result
    return self.get_insights(fields=fields, params=params)
  File "/home/ubuntu/.virtualenvs/acquiredatabase/lib/python3.7/site-packages/facebook_business/adobjects/adreportrun.py", line 214, in get_insights
    return request.execute()
  File "/home/ubuntu/.virtualenvs/acquiredatabase/lib/python3.7/site-packages/facebook_business/api.py", line 663, in execute
    cursor.load_next_page()
  File "/home/ubuntu/.virtualenvs/acquiredatabase/lib/python3.7/site-packages/facebook_business/api.py", line 830, in load_next_page
    params=self.params,
  File "/home/ubuntu/.virtualenvs/acquiredatabase/lib/python3.7/site-packages/facebook_business/api.py", line 336, in call
    raise fb_response.error()
facebook_business.exceptions.FacebookRequestError: 

  Message: Call was not successful
  Method:  GET
  Path:    https://graph.facebook.com/v4.0/707037786389629/insights
  Params:  {'limit': 1000}

  Status:  500
  Response:
    {
      "error": {
        "message": "An unexpected error has occurred. Please retry your request later.",
        "type": "OAuthException",
        "is_transient": true,
        "code": 2,
        "fbtrace_id": "AT6Loc6Uugaff1IXFDrEJoH"
      }
    }

